<robot name="mycar">

    <link name="base_footprint">
        <!-- visualization label -->
        <visual>
            <!-- 1.shape -->
            <geometry>
                <!-- 1.1 cube -->
                <box size="0.001 0.001 0.001" />
            </geometry>
        </visual>
    </link>
    <!--  1. chassis link-->
    <link name="base_link">
        <!-- visualization label -->
        <visual>
            <!-- 1.shape -->
            <geometry>
                <!-- 1.1 cube -->
                <box size="0.3 0.2 0.1" />
            </geometry>
            <origin xyz="0 0 0" rpy="0 0 0" />
            <material name="car_color">
                <color rgba="0.8 0.5 0 0.5" />
            </material>
        </visual>
    </link>
    <!-- 2. camera link -->
    <link name="camera">
        <!-- visualization label -->
        <visual>
            <!-- 1.shape -->
            <geometry>
                <!-- 1.1 cube -->
                <box size="0.02 0.05 0.05" />
            </geometry>
            <origin xyz="0 0 0.025" rpy="0 0 0" />
            <material name="camera_color">
                <color rgba="0 0 1 0.5" />
            </material>
        </visual>
    </link>
    <!-- base_footprint   2 base_link -->
    <joint name="link2footprint" type="fixed">
        <!-- parent link -->
        <parent link="base_footprint" />
        <!-- child link -->
        <child link="base_link" />
        <origin xyz="0 0 0.05" rpy="0 0 0" />
    </joint>

    <!-- joint -->
    <joint name="camera2base" type="continuous">
        <!-- parent link -->
        <parent link="base_link" />
        <!-- child link -->
        <child link="camera" />
        <origin xyz="0.12 0 0.05" rpy="0 0 0" />
        <axis xyz="0 0 1" />
    </joint>
</robot>